Workbook

Sheet AP_Subledger
A1: Invoice_ID | B1: Vendor | C1: Invoice_Date | D1: Due_Date | E1: Project_ID | F1: GL_Account | G1: Amount_Before_Tax | H1: Tax_Jurisdiction | I1: Tax_Amount | J1: Total_Invoice_Amount | K1: Paid_Flag | L1: Paid_Date | M1: Expected_Total | N1: Total_Mismatch_Flag | O1: Unpaid_AsOfYE | P1: AP_Match_Key | Q1: Bank_Match_Status
A2: INV2025-0001 | B2: Tri-County Services | C2: 45760 | D2: 45790 | E2: PRJ-1001 | F2: 5200-Subcontractors | G2: 4994.15 | H2: Pinellas | I2: 349.59 | J2: =IF(RAND()<0.23, M2 + RANDBETWEEN(-150,150)/100, M2) -> 5343.74 | K2: TRUE | L2: 45785 | M2: 5343.74 | N2: =IF(ABS(VALUE(M2) - VALUE(J2)) > 0.01, TRUE, FALSE) -> FALSE | O2: =IF(OR(K2=FALSE, IFERROR(L2>DATE(2025,12,31), TRUE)), TRUE, FALSE) -> FALSE | P2: =B2 & "|" & (-1 * J2) -> Tri-County Services|-5343.74 | Q2: =IF(K2=FALSE, "Unpaid", IF(ISNUMBER(MATCH(P2, Bank_Transactions!H:H, 0)), "Matched in Bank", "Paid but No Bank Match")) -> Paid but No Bank Match
A3: INV2025-0002 | B3: Atlantic Fiber Co | C3: 45760 | D3: 45790 | E3: PRJ-1001 | F3: 2100-AP-Trade | G3: 2949.39 | H3: Other_FL | I3: 176.96 | J3: =IF(RAND()<0.23, M3 + RANDBETWEEN(-150,150)/100, M3) -> 3126.35 | K3: TRUE | L3: 45788 | M3: 3126.35 | N3: =IF(ABS(VALUE(M3) - VALUE(J3)) > 0.01, TRUE, FALSE) -> FALSE | O3: =IF(OR(K3=FALSE, IFERROR(L3>DATE(2025,12,31), TRUE)), TRUE, FALSE) -> FALSE | P3: =B3 & "|" & (-1 * J3) -> Atlantic Fiber Co|-3126.35 | Q3: =IF(K3=FALSE, "Unpaid", IF(ISNUMBER(MATCH(P3, Bank_Transactions!H:H, 0)), "Matched in Bank", "Paid but No Bank Match")) -> Paid but No Bank Match
A4: INV2025-0003 | B4: Sunline Electrical | C4: 45788 | D4: 45818 | E4: PRJ-1001 | F4: 5100-Materials | G4: 24262.79 | H4: Pinellas | I4: 1698.4 | J4: =IF(RAND()<0.23, M4 + RANDBETWEEN(-150,150)/100, M4) -> 25961.19 | K4: TRUE | L4: 45830 | M4: 25961.19 | N4: =IF(ABS(VALUE(M4) - VALUE(J4)) > 0.01, TRUE, FALSE) -> FALSE | O4: =IF(OR(K4=FALSE, IFERROR(L4>DATE(2025,12,31), TRUE)), TRUE, FALSE) -> FALSE | P4: =B4 & "|" & (-1 * J4) -> Sunline Electrical|-25961.19 | Q4: =IF(K4=FALSE, "Unpaid", IF(ISNUMBER(MATCH(P4, Bank_Transactions!H:H, 0)), "Matched in Bank", "Paid but No Bank Match")) -> Paid but No Bank Match
A5: INV2025-0004 | B5: Tidal Contractors | C5: 45849 | D5: 45879 | E5: PRJ-4003 | F5: 9999-Suspense | G5: 15628.3 | H5: Other_FL | I5: 937.7 | J5: =IF(RAND()<0.23, M5 + RANDBETWEEN(-150,150)/100, M5) -> 16566 | K5: TRUE | L5: 45902 | M5: 16566 | N5: =IF(ABS(VALUE(M5) - VALUE(J5)) > 0.01, TRUE, FALSE) -> FALSE | O5: =IF(OR(K5=FALSE, IFERROR(L5>DATE(2025,12,31), TRUE)), TRUE, FALSE) -> FALSE | P5: =B5 & "|" & (-1 * J5) -> Tidal Contractors|-16566 | Q5: =IF(K5=FALSE, "Unpaid", IF(ISNUMBER(MATCH(P5, Bank_Transactions!H:H, 0)), "Matched in Bank", "Paid but No Bank Match")) -> Paid but No Bank Match
A6: INV2025-0005 | B6: Atlantic Fiber Co | C6: 45716 | D6: 45761 | E6: PRJ-4003 | F6: 5200-Subcontractors | G6: 1643.31 | H6: Hillsborough | I6: 123.25 | J6: =IF(RAND()<0.23, M6 + RANDBETWEEN(-150,150)/100, M6) -> 1767.02 | K6: FALSE | M6: 1766.56 | N6: =IF(ABS(VALUE(M6) - VALUE(J6)) > 0.01, TRUE, FALSE) -> TRUE | O6: =IF(OR(K6=FALSE, IFERROR(L6>DATE(2025,12,31), TRUE)), TRUE, FALSE) -> TRUE | P6: =B6 & "|" & (-1 * J6) -> Atlantic Fiber Co|-1767.02 | Q6: =IF(K6=FALSE, "Unpaid", IF(ISNUMBER(MATCH(P6, Bank_Transactions!H:H, 0)), "Matched in Bank", "Paid but No Bank Match")) -> Unpaid
A7: INV2025-0006 | B7: Tampa Grid Services | C7: 45928 | D7: 45973 | E7: PRJ-2001 | F7: 5200-Subcontractors | G7: 19736.81 | H7: Pinellas | I7: 1381.58 | J7: =IF(RAND()<0.23, M7 + RANDBETWEEN(-150,150)/100, M7) -> 21118.39 | K7: TRUE | L7: 45987 | M7: 21118.39 | N7: =IF(ABS(VALUE(M7) - VALUE(J7)) > 0.01, TRUE, FALSE) -> FALSE | O7: =IF(OR(K7=FALSE, IFERROR(L7>DATE(2025,12,31), TRUE)), TRUE, FALSE) -> FALSE | P7: =B7 & "|" & (-1 * J7) -> Tampa Grid Services|-21118.39 | Q7: =IF(K7=FALSE, "Unpaid", IF(ISNUMBER(MATCH(P7, Bank_Transactions!H:H, 0)), "Matched in Bank", "Paid but No Bank Match")) -> Paid but No Bank Match
A8: INV2025-0007 | B8: Atlantic Fiber Co | C8: 45901 | D8: 45946 | E8: PRJ-1001 | F8: 2100-AP-Trade | G8: 1638.04 | H8: Other_FL | I8: 98.28 | J8: =IF(RAND()<0.23, M8 + RANDBETWEEN(-150,150)/100, M8) -> 1736.32 | K8: TRUE | L8: 45926 | M8: 1736.32 | N8: =IF(ABS(VALUE(M8) - VALUE(J8)) > 0.01, TRUE, FALSE) -> FALSE | O8: =IF(OR(K8=FALSE, IFERROR(L8>DATE(2025,12,31), TRUE)), TRUE, FALSE) -> FALSE | P8: =B8 & "|" & (-1 * J8) -> Atlantic Fiber Co|-1736.32 | Q8: =IF(K8=FALSE, "Unpaid", IF(ISNUMBER(MATCH(P8, Bank_Transactions!H:H, 0)), "Matched in Bank", "Paid but No Bank Match")) -> Paid but No Bank Match
A9: INV2025-0008 | B9: Gulf Coast Telecom | C9: 45986 | D9: 46031 | E9: PRJ-2001 | F9: 5200-Subcontractors | G9: 23747.7 | H9: Hillsborough | I9: 1781.08 | J9: =IF(RAND()<0.23, M9 + RANDBETWEEN(-150,150)/100, M9) -> 25528.78 | K9: FALSE | M9: 25528.78 | N9: =IF(ABS(VALUE(M9) - VALUE(J9)) > 0.01, TRUE, FALSE) -> FALSE | O9: =IF(OR(K9=FALSE, IFERROR(L9>DATE(2025,12,31), TRUE)), TRUE, FALSE) -> TRUE | P9: =B9 & "|" & (-1 * J9) -> Gulf Coast Telecom|-25528.78 | Q9: =IF(K9=FALSE, "Unpaid", IF(ISNUMBER(MATCH(P9, Bank_Transactions!H:H, 0)), "Matched in Bank", "Paid but No Bank Match")) -> Unpaid
A10: INV2025-0009 | B10: BrightPower Partners | C10: 45899 | D10: 45944 | E10: PRJ-4003 | F10: 2100-AP-Trade | G10: 891.17 | H10: Other_FL | I10: 53.47 | J10: =IF(RAND()<0.23, M10 + RANDBETWEEN(-150,150)/100, M10) -> 944.64 | K10: TRUE | L10: 45963 | M10: 944.64 | N10: =IF(ABS(VALUE(M10) - VALUE(J10)) > 0.01, TRUE, FALSE) -> FALSE | O10: =IF(OR(K10=FALSE, IFERROR(L10>DATE(2025,12,31), TRUE)), TRUE, FALSE) -> FALSE | P10: =B10 & "|" & (-1 * J10) -> BrightPower Partners|-944.64 | Q10: =IF(K10=FALSE, "Unpaid", IF(ISNUMBER(MATCH(P10, Bank_Transactions!H:H, 0)), "Matched in Bank", "Paid but No Bank Match")) -> Paid but No Bank Match
A11: INV2025-0010 | B11: Gulf Coast Telecom | C11: 45921 | D11: 45966 | E11: PRJ-4003 | F11: 5200-Subcontractors | G11: 22778.35 | H11: Pinellas | I11: 1594.48 | J11: =IF(RAND()<0.23, M11 + RANDBETWEEN(-150,150)/100, M11) -> 24372.83 | K11: TRUE | L11: 45929 | M11: 24372.83 | N11: =IF(ABS(VALUE(M11) - VALUE(J11)) > 0.01, TRUE, FALSE) -> FALSE | O11: =IF(OR(K11=FALSE, IFERROR(L11>DATE(2025,12,31), TRUE)), TRUE, FALSE) -> FALSE | P11: =B11 & "|" & (-1 * J11) -> Gulf Coast Telecom|-24372.83 | Q11: =IF(K11=FALSE, "Unpaid", IF(ISNUMBER(MATCH(P11, Bank_Transactions!H:H, 0)), "Matched in Bank", "Paid but No Bank Match")) -> Paid but No Bank Match
A12: INV2025-0011 | B12: BrightPower Partners | C12: 45659 | D12: 45689 | E12: PRJ-1001 | F12: 5100-Materials | G12: 5594.57 | H12: Orange | I12: 363.65 | J12: =IF(RAND()<0.23, M12 + RANDBETWEEN(-150,150)/100, M12) -> 5958.91 | K12: TRUE | L12: 45726 | M12: 5958.22 | N12: =IF(ABS(VALUE(M12) - VALUE(J12)) > 0.01, TRUE, FALSE) -> TRUE | O12: =IF(OR(K12=FALSE, IFERROR(L12>DATE(2025,12,31), TRUE)), TRUE, FALSE) -> FALSE | P12: =B12 & "|" & (-1 * J12) -> BrightPower Partners|-5958.91 | Q12: =IF(K12=FALSE, "Unpaid", IF(ISNUMBER(MATCH(P12, Bank_Transactions!H:H, 0)), "Matched in Bank", "Paid but No Bank Match")) -> Paid but No Bank Match
A13: INV2025-0012 | B13: Gulf Coast Telecom | C13: 45875 | D13: 45905 | E13: PRJ-1001 | F13: 5300-Equipment-Rental | G13: 10181.18 | H13: Orange | I13: 661.78 | J13: =IF(RAND()<0.23, M13 + RANDBETWEEN(-150,150)/100, M13) -> 10842.96 | K13: FALSE | M13: 10842.96 | N13: =IF(ABS(VALUE(M13) - VALUE(J13)) > 0.01, TRUE, FALSE) -> FALSE | O13: =IF(OR(K13=FALSE, IFERROR(L13>DATE(2025,12,31), TRUE)), TRUE, FALSE) -> TRUE | P13: =B13 & "|" & (-1 * J13) -> Gulf Coast Telecom|-10842.96 | Q13: =IF(K13=FALSE, "Unpaid", IF(ISNUMBER(MATCH(P13, Bank_Transactions!H:H, 0)), "Matched in Bank", "Paid but No Bank Match")) -> Unpaid
A14: INV2025-0013 | B14: Sunshine Equipment | C14: 46008 | D14: 46053 | E14: PRJ-1002 | F14: 6000-Misc-Expense | G14: 2668.07 | H14: Orange | I14: 173.42 | J14: =IF(RAND()<0.23, M14 + RANDBETWEEN(-150,150)/100, M14) -> 2841.49 | K14: FALSE | M14: 2841.49 | N14: =IF(ABS(VALUE(M14) - VALUE(J14)) > 0.01, TRUE, FALSE) -> FALSE | O14: =IF(OR(K14=FALSE, IFERROR(L14>DATE(2025,12,31), TRUE)), TRUE, FALSE) -> TRUE | P14: =B14 & "|" & (-1 * J14) -> Sunshine Equipment|-2841.49 | Q14: =IF(K14=FALSE, "Unpaid", IF(ISNUMBER(MATCH(P14, Bank_Transactions!H:H, 0)), "Matched in Bank", "Paid but No Bank Match")) -> Unpaid
A15: INV2025-0014 | B15: Atlantic Fiber Co | C15: 45953 | D15: 45998 | E15: PRJ-1001 | F15: 5100-Materials | G15: 18809.34 | H15: Pinellas | I15: 1316.65 | J15: =IF(RAND()<0.23, M15 + RANDBETWEEN(-150,150)/100, M15) -> 20125.99 | K15: TRUE | L15: 45981 | M15: 20125.99 | N15: =IF(ABS(VALUE(M15) - VALUE(J15)) > 0.01, TRUE, FALSE) -> FALSE | O15: =IF(OR(K15=FALSE, IFERROR(L15>DATE(2025,12,31), TRUE)), TRUE, FALSE) -> FALSE | P15: =B15 & "|" & (-1 * J15) -> Atlantic Fiber Co|-20125.99 | Q15: =IF(K15=FALSE, "Unpaid", IF(ISNUMBER(MATCH(P15, Bank_Transactions!H:H, 0)), "Matched in Bank", "Paid but No Bank Match")) -> Paid but No Bank Match
A16: INV2025-0015 | B16: Tampa Grid Services | C16: 45874 | D16: 45919 | E16: PRJ-3005 | F16: 5200-Subcontractors | G16: 13796.05 | H16: Pinellas | I16: 965.72 | J16: =IF(RAND()<0.23, M16 + RANDBETWEEN(-150,150)/100, M16) -> 14761.77 | K16: TRUE | L16: 45893 | M16: 14761.77 | N16: =IF(ABS(VALUE(M16) - VALUE(J16)) > 0.01, TRUE, FALSE) -> FALSE | O16: =IF(OR(K16=FALSE, IFERROR(L16>DATE(2025,12,31), TRUE)), TRUE, FALSE) -> FALSE | P16: =B16 & "|" & (-1 * J16) -> Tampa Grid Services|-14761.77 | Q16: =IF(K16=FALSE, "Unpaid", IF(ISNUMBER(MATCH(P16, Bank_Transactions!H:H, 0)), "Matched in Bank", "Paid but No Bank Match")) -> Paid but No Bank Match
A17: INV2025-0016 | B17: Tri-County Services | C17: 45958 | D17: 46003 | E17: PRJ-1001 | F17: 5100-Materials | G17: 24678.73 | H17: Hillsborough | I17: 3701.8 | J17: =IF(RAND()<0.23, M17 + RANDBETWEEN(-150,150)/100, M17) -> 28380.53 | K17: TRUE | L17: 45970 | M17: 28380.53 | N17: =IF(ABS(VALUE(M17) - VALUE(J17)) > 0.01, TRUE, FALSE) -> FALSE | O17: =IF(OR(K17=FALSE, IFERROR(L17>DATE(2025,12,31), TRUE)), TRUE, FALSE) -> FALSE | P17: =B17 & "|" & (-1 * J17) -> Tri-County Services|-28380.53 | Q17: =IF(K17=FALSE, "Unpaid", IF(ISNUMBER(MATCH(P17, Bank_Transactions!H:H, 0)), "Matched in Bank", "Paid but No Bank Match")) -> Paid but No Bank Match
A18: INV2025-0017 | B18: Florida Line Crew LLC | C18: 45720 | D18: 45765 | E18: PRJ-2001 | F18: 2100-AP-Trade | G18: 17818 | H18: Pinellas | I18: 1247.26 | J18: =IF(RAND()<0.23, M18 + RANDBETWEEN(-150,150)/100, M18) -> 19065.69 | K18: TRUE | L18: 45757 | M18: 19065.26 | N18: =IF(ABS(VALUE(M18) - VALUE(J18)) > 0.01, TRUE, FALSE) -> TRUE | O18: =IF(OR(K18=FALSE, IFERROR(L18>DATE(2025,12,31), TRUE)), TRUE, FALSE) -> FALSE | P18: =B18 & "|" & (-1 * J18) -> Florida Line Crew LLC|-19065.69 | Q18: =IF(K18=FALSE, "Unpaid", IF(ISNUMBER(MATCH(P18, Bank_Transactions!H:H, 0)), "Matched in Bank", "Paid but No Bank Match")) -> Paid but No Bank Match
A19: INV2025-0018 | B19: Skyline Engineering | C19: 45918 | D19: 45963 | E19: PRJ-1002 | F19: 8900-Other | G19: 16451.39 | H19: Other_FL | I19: 1974.16 | J19: =IF(RAND()<0.23, M19 + RANDBETWEEN(-150,150)/100, M19) -> 18425.55 | K19: FALSE | M19: 18425.55 | N19: =IF(ABS(VALUE(M19) - VALUE(J19)) > 0.01, TRUE, FALSE) -> FALSE | O19: =IF(OR(K19=FALSE, IFERROR(L19>DATE(2025,12,31), TRUE)), TRUE, FALSE) -> TRUE | P19: =B19 & "|" & (-1 * J19) -> Skyline Engineering|-18425.55 | Q19: =IF(K19=FALSE, "Unpaid", IF(ISNUMBER(MATCH(P19, Bank_Transactions!H:H, 0)), "Matched in Bank", "Paid but No Bank Match")) -> Unpaid
A20: INV2025-0019 | B20: Bay Area Rentals | C20: 45858 | D20: 45903 | E20: PRJ-1002 | F20: 5200-Subcontractors | G20: 8607 | H20: Pinellas | I20: 602.49 | J20: =IF(RAND()<0.23, M20 + RANDBETWEEN(-150,150)/100, M20) -> 9209.49 | K20: TRUE | L20: 45885 | M20: 9209.49 | N20: =IF(ABS(VALUE(M20) - VALUE(J20)) > 0.01, TRUE, FALSE) -> FALSE | O20: =IF(OR(K20=FALSE, IFERROR(L20>DATE(2025,12,31), TRUE)), TRUE, FALSE) -> FALSE | P20: =B20 & "|" & (-1 * J20) -> Bay Area Rentals|-9209.49 | Q20: =IF(K20=FALSE, "Unpaid", IF(ISNUMBER(MATCH(P20, Bank_Transactions!H:H, 0)), "Matched in Bank", "Paid but No Bank Match")) -> Paid but No Bank Match
A21: INV2025-0020 | B21: Atlantic Fiber Co | C21: 45719 | D21: 45764 | E21: PRJ-4003 | F21: 5300-Equipment-Rental | G21: 18375.35 | H21: Other_FL | I21: 1102.52 | J21: =IF(RAND()<0.23, M21 + RANDBETWEEN(-150,150)/100, M21) -> 19477.87 | K21: TRUE | L21: 45758 | M21: 19477.87 | N21: =IF(ABS(VALUE(M21) - VALUE(J21)) > 0.01, TRUE, FALSE) -> FALSE | O21: =IF(OR(K21=FALSE, IFERROR(L21>DATE(2025,12,31), TRUE)), TRUE, FALSE) -> FALSE | P21: =B21 & "|" & (-1 * J21) -> Atlantic Fiber Co|-19477.87 | Q21: =IF(K21=FALSE, "Unpaid", IF(ISNUMBER(MATCH(P21, Bank_Transactions!H:H, 0)), "Matched in Bank", "Paid but No Bank Match")) -> Paid but No Bank Match
A22: INV2025-0021 | B22: Florida Line Crew LLC | C22: 45884 | D22: 45914 | E22: PRJ-1002 | F22: 5300-Equipment-Rental | G22: 17974.5 | H22: Hillsborough | I22: 1348.09 | J22: =IF(RAND()<0.23, M22 + RANDBETWEEN(-150,150)/100, M22) -> 19323.88 | K22: TRUE | L22: 45902 | M22: 19322.59 | N22: =IF(ABS(VALUE(M22) - VALUE(J22)) > 0.01, TRUE, FALSE) -> TRUE | O22: =IF(OR(K22=FALSE, IFERROR(L22>DATE(2025,12,31), TRUE)), TRUE, FALSE) -> FALSE | P22: =B22 & "|" & (-1 * J22) -> Florida Line Crew LLC|-19323.88 | Q22: =IF(K22=FALSE, "Unpaid", IF(ISNUMBER(MATCH(P22, Bank_Transactions!H:H, 0)), "Matched in Bank", "Paid but No Bank Match")) -> Paid but No Bank Match
A23: INV2025-0022 | B23: Sunline Electrical | C23: 46016 | D23: 46046 | E23: PRJ-1002 | F23: 5100-Materials | G23: 17911.24 | H23: Other_FL | I23: 1074.67 | J23: =IF(RAND()<0.23, M23 + RANDBETWEEN(-150,150)/100, M23) -> 18985.91 | K23: FALSE | M23: 18985.91 | N23: =IF(ABS(VALUE(M23) - VALUE(J23)) > 0.01, TRUE, FALSE) -> FALSE | O23: =IF(OR(K23=FALSE, IFERROR(L23>DATE(2025,12,31), TRUE)), TRUE, FALSE) -> TRUE | P23: =B23 & "|" & (-1 * J23) -> Sunline Electrical|-18985.91 | Q23: =IF(K23=FALSE, "Unpaid", IF(ISNUMBER(MATCH(P23, Bank_Transactions!H:H, 0)), "Matched in Bank", "Paid but No Bank Match")) -> Unpaid
A24: INV2025-0023 | B24: Skyline Engineering | C24: 45720 | D24: 45750 | E24: PRJ-3005 | F24: 5300-Equipment-Rental | G24: 12146.57 | H24: Other_FL | I24: 728.79 | J24: =IF(RAND()<0.23, M24 + RANDBETWEEN(-150,150)/100, M24) -> 12875.36 | K24: TRUE | L24: 45728 | M24: 12875.36 | N24: =IF(ABS(VALUE(M24) - VALUE(J24)) > 0.01, TRUE, FALSE) -> FALSE | O24: =IF(OR(K24=FALSE, IFERROR(L24>DATE(2025,12,31), TRUE)), TRUE, FALSE) -> FALSE | P24: =B24 & "|" & (-1 * J24) -> Skyline Engineering|-12875.36 | Q24: =IF(K24=FALSE, "Unpaid", IF(ISNUMBER(MATCH(P24, Bank_Transactions!H:H, 0)), "Matched in Bank", "Paid but No Bank Match")) -> Paid but No Bank Match
A25: INV2025-0024 | B25: Tidal Contractors | C25: 45879 | D25: 45924 | E25: PRJ-4003 | F25: 2100-AP-Trade | G25: 15308.23 | H25: Hillsborough | I25: 1148.12 | J25: =IF(RAND()<0.23, M25 + RANDBETWEEN(-150,150)/100, M25) -> 16456.35 | K25: TRUE | L25: 45912 | M25: 16456.35 | N25: =IF(ABS(VALUE(M25) - VALUE(J25)) > 0.01, TRUE, FALSE) -> FALSE | O25: =IF(OR(K25=FALSE, IFERROR(L25>DATE(2025,12,31), TRUE)), TRUE, FALSE) -> FALSE | P25: =B25 & "|" & (-1 * J25) -> Tidal Contractors|-16456.35 | Q25: =IF(K25=FALSE, "Unpaid", IF(ISNUMBER(MATCH(P25, Bank_Transactions!H:H, 0)), "Matched in Bank", "Paid but No Bank Match")) -> Paid but No Bank Match
A26: INV2025-0025 | B26: Tri-County Services | C26: 45693 | D26: 45738 | E26: PRJ-2001 | F26: 9999-Suspense | G26: 15172.2 | H26: Orange | I26: 986.19 | J26: =IF(RAND()<0.23, M26 + RANDBETWEEN(-150,150)/100, M26) -> 16158.39 | K26: TRUE | L26: 45725 | M26: 16158.39 | N26: =IF(ABS(VALUE(M26) - VALUE(J26)) > 0.01, TRUE, FALSE) -> FALSE | O26: =IF(OR(K26=FALSE, IFERROR(L26>DATE(2025,12,31), TRUE)), TRUE, FALSE) -> FALSE | P26: =B26 & "|" & (-1 * J26) -> Tri-County Services|-16158.39 | Q26: =IF(K26=FALSE, "Unpaid", IF(ISNUMBER(MATCH(P26, Bank_Transactions!H:H, 0)), "Matched in Bank", "Paid but No Bank Match")) -> Paid but No Bank Match
A27: INV2025-0026 | B27: Bay Area Rentals | C27: 45723 | D27: 45753 | E27: PRJ-3005 | F27: 2100-AP-Trade | G27: 7743.03 | H27: Orange | I27: 503.3 | J27: =IF(RAND()<0.23, M27 + RANDBETWEEN(-150,150)/100, M27) -> 8246.33 | K27: TRUE | L27: 45755 | M27: 8246.33 | N27: =IF(ABS(VALUE(M27) - VALUE(J27)) > 0.01, TRUE, FALSE) -> FALSE | O27: =IF(OR(K27=FALSE, IFERROR(L27>DATE(2025,12,31), TRUE)), TRUE, FALSE) -> FALSE | P27: =B27 & "|" & (-1 * J27) -> Bay Area Rentals|-8246.33 | Q27: =IF(K27=FALSE, "Unpaid", IF(ISNUMBER(MATCH(P27, Bank_Transactions!H:H, 0)), "Matched in Bank", "Paid but No Bank Match")) -> Paid but No Bank Match
A28: INV2025-0027 | B28: Tidal Contractors | C28: 45685 | D28: 45715 | E28: PRJ-4003 | F28: 2100-AP-Trade | G28: 10704.49 | H28: Orange | I28: 695.79 | J28: =IF(RAND()<0.23, M28 + RANDBETWEEN(-150,150)/100, M28) -> 11400.28 | K28: FALSE | M28: 11400.28 | N28: =IF(ABS(VALUE(M28) - VALUE(J28)) > 0.01, TRUE, FALSE) -> FALSE | O28: =IF(OR(K28=FALSE, IFERROR(L28>DATE(2025,12,31), TRUE)), TRUE, FALSE) -> TRUE | P28: =B28 & "|" & (-1 * J28) -> Tidal Contractors|-11400.28 | Q28: =IF(K28=FALSE, "Unpaid", IF(ISNUMBER(MATCH(P28, Bank_Transactions!H:H, 0)), "Matched in Bank", "Paid but No Bank Match")) -> Unpaid
A29: INV2025-0028 | B29: Tri-County Services | C29: 45785 | D29: 45815 | E29: PRJ-1002 | F29: 5200-Subcontractors | G29: 22454.24 | H29: Pinellas | I29: 1571.8 | J29: =IF(RAND()<0.23, M29 + RANDBETWEEN(-150,150)/100, M29) -> 24027.04 | K29: TRUE | L29: 45790 | M29: 24026.04 | N29: =IF(ABS(VALUE(M29) - VALUE(J29)) > 0.01, TRUE, FALSE) -> TRUE | O29: =IF(OR(K29=FALSE, IFERROR(L29>DATE(2025,12,31), TRUE)), TRUE, FALSE) -> FALSE | P29: =B29 & "|" & (-1 * J29) -> Tri-County Services|-24027.04 | Q29: =IF(K29=FALSE, "Unpaid", IF(ISNUMBER(MATCH(P29, Bank_Transactions!H:H, 0)), "Matched in Bank", "Paid but No Bank Match")) -> Paid but No Bank Match
A30: INV2025-0029 | B30: Tidal Contractors | C30: 45940 | D30: 45970 | E30: PRJ-4003 | F30: 5200-Subcontractors | G30: 20541.36 | H30: Other_FL | I30: 1232.48 | J30: =IF(RAND()<0.23, M30 + RANDBETWEEN(-150,150)/100, M30) -> 21773.17 | K30: FALSE | M30: 21773.84 | N30: =IF(ABS(VALUE(M30) - VALUE(J30)) > 0.01, TRUE, FALSE) -> TRUE | O30: =IF(OR(K30=FALSE, IFERROR(L30>DATE(2025,12,31), TRUE)), TRUE, FALSE) -> TRUE | P30: =B30 & "|" & (-1 * J30) -> Tidal Contractors|-21773.17 | Q30: =IF(K30=FALSE, "Unpaid", IF(ISNUMBER(MATCH(P30, Bank_Transactions!H:H, 0)), "Matched in Bank", "Paid but No Bank Match")) -> Unpaid
A31: INV2025-0030 | B31: Sunline Electrical | C31: 46016 | D31: 46046 | E31: PRJ-2001 | F31: 5200-Subcontractors | G31: 13585.19 | H31: Pinellas | I31: 950.96 | J31: =IF(RAND()<0.23, M31 + RANDBETWEEN(-150,150)/100, M31) -> 14535.45 | K31: FALSE | M31: 14536.15 | N31: =IF(ABS(VALUE(M31) - VALUE(J31)) > 0.01, TRUE, FALSE) -> TRUE | O31: =IF(OR(K31=FALSE, IFERROR(L31>DATE(2025,12,31), TRUE)), TRUE, FALSE) -> TRUE | P31: =B31 & "|" & (-1 * J31) -> Sunline Electrical|-14535.45 | Q31: =IF(K31=FALSE, "Unpaid", IF(ISNUMBER(MATCH(P31, Bank_Transactions!H:H, 0)), "Matched in Bank", "Paid but No Bank Match")) -> Unpaid
A32: INV2025-0031 | B32: Sunline Electrical | C32: 45891 | D32: 45921 | E32: PRJ-4003 | F32: 2100-AP-Trade | G32: 23601.29 | H32: Hillsborough | I32: 1770.1 | J32: =IF(RAND()<0.23, M32 + RANDBETWEEN(-150,150)/100, M32) -> 25371.39 | K32: TRUE | L32: 45947 | M32: 25371.39 | N32: =IF(ABS(VALUE(M32) - VALUE(J32)) > 0.01, TRUE, FALSE) -> FALSE | O32: =IF(OR(K32=FALSE, IFERROR(L32>DATE(2025,12,31), TRUE)), TRUE, FALSE) -> FALSE | P32: =B32 & "|" & (-1 * J32) -> Sunline Electrical|-25371.39 | Q32: =IF(K32=FALSE, "Unpaid", IF(ISNUMBER(MATCH(P32, Bank_Transactions!H:H, 0)), "Matched in Bank", "Paid but No Bank Match")) -> Paid but No Bank Match
A33: INV2025-0032 | B33: BrightPower Partners | C33: 45770 | D33: 45815 | E33: PRJ-1001 | F33: 5100-Materials | G33: 6720.93 | H33: Pinellas | I33: 470.47 | J33: =IF(RAND()<0.23, M33 + RANDBETWEEN(-150,150)/100, M33) -> 7191.4 | K33: TRUE | L33: 45813 | M33: 7191.4 | N33: =IF(ABS(VALUE(M33) - VALUE(J33)) > 0.01, TRUE, FALSE) -> FALSE | O33: =IF(OR(K33=FALSE, IFERROR(L33>DATE(2025,12,31), TRUE)), TRUE, FALSE) -> FALSE | P33: =B33 & "|" & (-1 * J33) -> BrightPower Partners|-7191.4 | Q33: =IF(K33=FALSE, "Unpaid", IF(ISNUMBER(MATCH(P33, Bank_Transactions!H:H, 0)), "Matched in Bank", "Paid but No Bank Match")) -> Paid but No Bank Match
A34: INV2025-0033 | B34: Tri-County Services | C34: 45770 | D34: 45815 | E34: PRJ-4003 | F34: 5100-Materials | G34: 24944.64 | H34: Orange | I34: 1621.4 | J34: =IF(RAND()<0.23, M34 + RANDBETWEEN(-150,150)/100, M34) -> 26565.24 | K34: TRUE | L34: 45776 | M34: 26566.04 | N34: =IF(ABS(VALUE(M34) - VALUE(J34)) > 0.01, TRUE, FALSE) -> TRUE | O34: =IF(OR(K34=FALSE, IFERROR(L34>DATE(2025,12,31), TRUE)), TRUE, FALSE) -> FALSE | P34: =B34 & "|" & (-1 * J34) -> Tri-County Services|-26565.24 | Q34: =IF(K34=FALSE, "Unpaid", IF(ISNUMBER(MATCH(P34, Bank_Transactions!H:H, 0)), "Matched in Bank", "Paid but No Bank Match")) -> Paid but No Bank Match
A35: INV2025-0034 | B35: Tidal Contractors | C35: 45787 | D35: 45832 | E35: PRJ-1002 | F35: 5100-Materials | G35: 1309.74 | H35: Orange | I35: 85.13 | J35: =IF(RAND()<0.23, M35 + RANDBETWEEN(-150,150)/100, M35) -> 1394.87 | K35: TRUE | L35: 45792 | M35: 1394.87 | N35: =IF(ABS(VALUE(M35) - VALUE(J35)) > 0.01, TRUE, FALSE) -> FALSE | O35: =IF(OR(K35=FALSE, IFERROR(L35>DATE(2025,12,31), TRUE)), TRUE, FALSE) -> FALSE | P35: =B35 & "|" & (-1 * J35) -> Tidal Contractors|-1394.87 | Q35: =IF(K35=FALSE, "Unpaid", IF(ISNUMBER(MATCH(P35, Bank_Transactions!H:H, 0)), "Matched in Bank", "Paid but No Bank Match")) -> Paid but No Bank Match
A36: INV2025-0035 | B36: Bay Area Rentals | C36: 45783 | D36: 45828 | E36: PRJ-3005 | F36: 5300-Equipment-Rental | G36: 12491.59 | H36: Hillsborough | I36: 936.87 | J36: =IF(RAND()<0.23, M36 + RANDBETWEEN(-150,150)/100, M36) -> 13428.46 | K36: FALSE | M36: 13428.46 | N36: =IF(ABS(VALUE(M36) - VALUE(J36)) > 0.01, TRUE, FALSE) -> FALSE | O36: =IF(OR(K36=FALSE, IFERROR(L36>DATE(2025,12,31), TRUE)), TRUE, FALSE) -> TRUE | P36: =B36 & "|" & (-1 * J36) -> Bay Area Rentals|-13428.46 | Q36: =IF(K36=FALSE, "Unpaid", IF(ISNUMBER(MATCH(P36, Bank_Transactions!H:H, 0)), "Matched in Bank", "Paid but No Bank Match")) -> Unpaid
A37: INV2025-0036 | B37: Atlantic Fiber Co | C37: 45904 | D37: 45934 | E37: PRJ-1001 | F37: 5200-Subcontractors | G37: 19159.68 | H37: Hillsborough | I37: 1436.98 | J37: =IF(RAND()<0.23, M37 + RANDBETWEEN(-150,150)/100, M37) -> 20596.66 | K37: TRUE | L37: 45946 | M37: 20596.66 | N37: =IF(ABS(VALUE(M37) - VALUE(J37)) > 0.01, TRUE, FALSE) -> FALSE | O37: =IF(OR(K37=FALSE, IFERROR(L37>DATE(2025,12,31), TRUE)), TRUE, FALSE) -> FALSE | P37: =B37 & "|" & (-1 * J37) -> Atlantic Fiber Co|-20596.66 | Q37: =IF(K37=FALSE, "Unpaid", IF(ISNUMBER(MATCH(P37, Bank_Transactions!H:H, 0)), "Matched in Bank", "Paid but No Bank Match")) -> Paid but No Bank Match
A38: INV2025-0037 | B38: Skyline Engineering | C38: 45937 | D38: 45967 | E38: PRJ-4003 | F38: 5100-Materials | G38: 24593.87 | H38: Hillsborough | I38: 1844.54 | J38: =IF(RAND()<0.23, M38 + RANDBETWEEN(-150,150)/100, M38) -> 26438.41 | K38: TRUE | L38: 45957 | M38: 26438.41 | N38: =IF(ABS(VALUE(M38) - VALUE(J38)) > 0.01, TRUE, FALSE) -> FALSE | O38: =IF(OR(K38=FALSE, IFERROR(L38>DATE(2025,12,31), TRUE)), TRUE, FALSE) -> FALSE | P38: =B38 & "|" & (-1 * J38) -> Skyline Engineering|-26438.41 | Q38: =IF(K38=FALSE, "Unpaid", IF(ISNUMBER(MATCH(P38, Bank_Transactions!H:H, 0)), "Matched in Bank", "Paid but No Bank Match")) -> Paid but No Bank Match
A39: INV2025-0038 | B39: Gulf Coast Telecom | C39: 45754 | D39: 45784 | E39: PRJ-1002 | F39: 2100-AP-Trade | G39: 12950.87 | H39: Hillsborough | I39: 971.32 | J39: =IF(RAND()<0.23, M39 + RANDBETWEEN(-150,150)/100, M39) -> 13922.19 | K39: TRUE | L39: 45761 | M39: 13922.19 | N39: =IF(ABS(VALUE(M39) - VALUE(J39)) > 0.01, TRUE, FALSE) -> FALSE | O39: =IF(OR(K39=FALSE, IFERROR(L39>DATE(2025,12,31), TRUE)), TRUE, FALSE) -> FALSE | P39: =B39 & "|" & (-1 * J39) -> Gulf Coast Telecom|-13922.19 | Q39: =IF(K39=FALSE, "Unpaid", IF(ISNUMBER(MATCH(P39, Bank_Transactions!H:H, 0)), "Matched in Bank", "Paid but No Bank Match")) -> Paid but No Bank Match
A40: INV2025-0039 | B40: Florida Line Crew LLC | C40: 45805 | D40: 45835 | E40: PRJ-4003 | F40: 5100-Materials | G40: 5895.91 | H40: Orange | I40: 383.23 | J40: =IF(RAND()<0.23, M40 + RANDBETWEEN(-150,150)/100, M40) -> 6279.14 | K40: TRUE | L40: 45828 | M40: 6279.14 | N40: =IF(ABS(VALUE(M40) - VALUE(J40)) > 0.01, TRUE, FALSE) -> FALSE | O40: =IF(OR(K40=FALSE, IFERROR(L40>DATE(2025,12,31), TRUE)), TRUE, FALSE) -> FALSE | P40: =B40 & "|" & (-1 * J40) -> Florida Line Crew LLC|-6279.14 | Q40: =IF(K40=FALSE, "Unpaid", IF(ISNUMBER(MATCH(P40, Bank_Transactions!H:H, 0)), "Matched in Bank", "Paid but No Bank Match")) -> Paid but No Bank Match
...

Sheet Bank_Txns
A1: Bank_Txn_ID | B1: Date | C1: Vendor | D1: Description | E1: Amount | F1: Check_ACH | G1: Cleared_Flag | H1: Match_Key | I1: Duplicate_Payment | J1: Duplicate_Payment_Flag
A2: BTXN-00001 | B2: 2025-05-08 | C2: Tri-County Services | D2: Payment for INV2025-0001 | E2: -5343.74 | F2: ACH | G2: True | H2: =C2 & "|" & E2 -> Tri-County Services|-5343.74 | I2: =COUNTIF(H:H, H2) -> 1 | J2: =IF(I2>1, "Duplicate Payment", "OK") -> OK
A3: BTXN-00002 | B3: 2025-05-11 | C3: Atlantic Fiber Co | D3: Payment for INV2025-0002 | E3: -3126.35 | F3: ACH | G3: True | H3: =C3 & "|" & E3 -> Atlantic Fiber Co|-3126.35 | I3: =COUNTIF(H:H, H3) -> 1 | J3: =IF(I3>1, "Duplicate Payment", "OK") -> OK
A4: BTXN-00003 | B4: 2025-06-22 | C4: Sunline Electrical | D4: Payment for INV2025-0003 | E4: -25961.19 | F4: Check | G4: True | H4: =C4 & "|" & E4 -> Sunline Electrical|-25961.19 | I4: =COUNTIF(H:H, H4) -> 1 | J4: =IF(I4>1, "Duplicate Payment", "OK") -> OK
A5: BTXN-00004 | B5: 2025-09-02 | C5: Tidal Contractors | D5: Payment for INV2025-0004 | E5: -16566 | F5: Check | G5: True | H5: =C5 & "|" & E5 -> Tidal Contractors|-16566 | I5: =COUNTIF(H:H, H5) -> 1 | J5: =IF(I5>1, "Duplicate Payment", "OK") -> OK
A6: BTXN-00005 | B6: 2025-11-26 | C6: Tampa Grid Services | D6: Payment for INV2025-0006 | E6: -21118.39 | F6: Check | G6: True | H6: =C6 & "|" & E6 -> Tampa Grid Services|-21118.39 | I6: =COUNTIF(H:H, H6) -> 1 | J6: =IF(I6>1, "Duplicate Payment", "OK") -> OK
A7: BTXN-00006 | B7: 2025-09-26 | C7: Atlantic Fiber Co | D7: Payment for INV2025-0007 | E7: -1736.32 | F7: ACH | G7: True | H7: =C7 & "|" & E7 -> Atlantic Fiber Co|-1736.32 | I7: =COUNTIF(H:H, H7) -> 1 | J7: =IF(I7>1, "Duplicate Payment", "OK") -> OK
A8: BTXN-00007 | B8: 2025-11-02 | C8: BrightPower Partners | D8: Payment for INV2025-0009 | E8: -944.64 | F8: ACH | G8: True | H8: =C8 & "|" & E8 -> BrightPower Partners|-944.64 | I8: =COUNTIF(H:H, H8) -> 1 | J8: =IF(I8>1, "Duplicate Payment", "OK") -> OK
A9: BTXN-00008 | B9: 2025-09-29 | C9: Gulf Coast Telecom | D9: Payment for INV2025-0010 | E9: -24372.83 | F9: ACH | G9: True | H9: =C9 & "|" & E9 -> Gulf Coast Telecom|-24372.83 | I9: =COUNTIF(H:H, H9) -> 1 | J9: =IF(I9>1, "Duplicate Payment", "OK") -> OK
A10: BTXN-00009 | B10: 2025-03-10 | C10: BrightPower Partners | D10: Payment for INV2025-0011 | E10: -5958.22 | F10: ACH | G10: True | H10: =C10 & "|" & E10 -> BrightPower Partners|-5958.22 | I10: =COUNTIF(H:H, H10) -> 1 | J10: =IF(I10>1, "Duplicate Payment", "OK") -> OK
A11: BTXN-00010 | B11: 2025-11-20 | C11: Atlantic Fiber Co | D11: Payment for INV2025-0014 | E11: -20125.99 | F11: ACH | G11: True | H11: =C11 & "|" & E11 -> Atlantic Fiber Co|-20125.99 | I11: =COUNTIF(H:H, H11) -> 1 | J11: =IF(I11>1, "Duplicate Payment", "OK") -> OK
A12: BTXN-00011 | B12: 2025-08-24 | C12: Tampa Grid Services | D12: Payment for INV2025-0015 | E12: -14761.77 | F12: Check | G12: True | H12: =C12 & "|" & E12 -> Tampa Grid Services|-14761.77 | I12: =COUNTIF(H:H, H12) -> 1 | J12: =IF(I12>1, "Duplicate Payment", "OK") -> OK
A13: BTXN-00012 | B13: 2025-11-09 | C13: Tri-County Services | D13: Payment for INV2025-0016 | E13: -28380.53 | F13: Check | G13: True | H13: =C13 & "|" & E13 -> Tri-County Services|-28380.53 | I13: =COUNTIF(H:H, H13) -> 1 | J13: =IF(I13>1, "Duplicate Payment", "OK") -> OK
... A284: BTXN-00283 | B284: 2025-07-15 | C284: BrightPower Partners | D284: Unmatched vendor payment | E284: -644.79 | F284: ACH | G284: True | H284: =C284 & "|" & E284 -> BrightPower Partners|-644.79 | I284: =COUNTIF(H:H, H284) -> 1 | J284: =IF(I284>1, "Duplicate Payment", "OK") -> OK

Sheet GL_AP_Control
A1: Period | B1: AP_Control_Balance | C1: AP_Unpaid_Subledger_Balance
A2: 2025-01 | B2: 350312.46 | C2: 349676.7
A3: 2025-02 | B3: 328655.55 | C3: 337943.22
A4: 2025-03 | B4: 626503.85 | C4: 609374.74
A5: 2025-04 | B5: 672493.32 | C5: 660652.54
A6: 2025-05 | B6: 742770.87 | C6: 752120.23
A7: 2025-06 | B7: 826655.98 | C7: 803516.15
A8: 2025-07 | B8: 765662.09 | C8: 761010.11
A9: 2025-08 | B9: 811937.22 | C9: 807941.66
A10: 2025-09 | B10: 840396.75 | C10: 828071.41
A11: 2025-10 | B11: 992548.61 | C11: 974322.75
A12: 2025-11 | B12: 1061233.14 | C12: 1051362.2
A13: 2025-12 | B13: 1109192.51 | C13: 1134508.22

Sheet Tax_Detail
A1: Invoice_ID | B1: State | C1: Taxable_Amount | D1: Tax_Rate | E1: Calculated_Tax | F1: GL_Tax_Liability_Account | G1: Recalc_Tax | H1: Tax_Mismatch_Flag | I1: Correct_Tax_Rate | J1: Correct_Rate_Flag
A2: INV2025-0001 | B2: FL | C2: 4994.15 | D2: 0.07 | E2: =IF(RAND() < 0.12, CHOOSE(RANDBETWEEN(1,4), 0, ROUND(C2 * (D2 - 0.01), 2), ROUND(C2 * (D2 + 0.01), 2), ROUND(C2 * D2 * 2, 2) ), ROUND(C2 * D2, 2) ) -> 349.59 | F2: 2020-SalesUseTaxPayable | G2: =ROUND(C2 * D2, 2) -> 349.59 | H2: =IF(ABS(E2 - G2) > 0.01, "Mismatch", "OK") -> OK | I2: {=IFERROR(XLOOKUP(XLOOKUP(A2, AP_Subledger!A:A, AP_Subledger!H:H), Tax_Rates_Reference!A:A, Tax_Rates_Reference!C:C), "")} -> 0.07 | J2: =IF(I2="", "", IF(ABS(D2 - I2) < 0.0001, TRUE, FALSE)) -> TRUE
A3: INV2025-0002 | B3: FL | C3: 2949.39 | D3: 0.06 | E3: =IF(RAND() < 0.12, CHOOSE(RANDBETWEEN(1,4), 0, ROUND(C3 * (D3 - 0.01), 2), ROUND(C3 * (D3 + 0.01), 2), ROUND(C3 * D3 * 2, 2) ), ROUND(C3 * D3, 2) ) -> 176.96 | F3: 2020-SalesUseTaxPayable | G3: =ROUND(C3 * D3, 2) -> 176.96 | H3: =IF(ABS(E3 - G3) > 0.01, "Mismatch", "OK") -> OK | I3: {=IFERROR(XLOOKUP(XLOOKUP(A3, AP_Subledger!A:A, AP_Subledger!H:H), Tax_Rates_Reference!A:A, Tax_Rates_Reference!C:C), "")} -> 0.06 | J3: =IF(I3="", "", IF(ABS(D3 - I3) < 0.0001, TRUE, FALSE)) -> TRUE
A4: INV2025-0003 | B4: FL | C4: 24262.79 | D4: 0.07 | E4: =IF(RAND() < 0.12, CHOOSE(RANDBETWEEN(1,4), 0, ROUND(C4 * (D4 - 0.01), 2), ROUND(C4 * (D4 + 0.01), 2), ROUND(C4 * D4 * 2, 2) ), ROUND(C4 * D4, 2) ) -> 1698.4 | F4: 2020-SalesUseTaxPayable | G4: =ROUND(C4 * D4, 2) -> 1698.4 | H4: =IF(ABS(E4 - G4) > 0.01, "Mismatch", "OK") -> OK | I4: {=IFERROR(XLOOKUP(XLOOKUP(A4, AP_Subledger!A:A, AP_Subledger!H:H), Tax_Rates_Reference!A:A, Tax_Rates_Reference!C:C), "")} -> 0.07 | J4: =IF(I4="", "", IF(ABS(D4 - I4) < 0.0001, TRUE, FALSE)) -> TRUE
A5: INV2025-0004 | B5: FL | C5: 15628.3 | D5: 0.06 | E5: =IF(RAND() < 0.12, CHOOSE(RANDBETWEEN(1,4), 0, ROUND(C5 * (D5 - 0.01), 2), ROUND(C5 * (D5 + 0.01), 2), ROUND(C5 * D5 * 2, 2) ), ROUND(C5 * D5, 2) ) -> 937.7 | F5: 2020-SalesUseTaxPayable | G5: =ROUND(C5 * D5, 2) -> 937.7 | H5: =IF(ABS(E5 - G5) > 0.01, "Mismatch", "OK") -> OK | I5: {=IFERROR(XLOOKUP(XLOOKUP(A5, AP_Subledger!A:A, AP_Subledger!H:H), Tax_Rates_Reference!A:A, Tax_Rates_Reference!C:C), "")} -> 0.06 | J5: =IF(I5="", "", IF(ABS(D5 - I5) < 0.0001, TRUE, FALSE)) -> TRUE
A6: INV2025-0005 | B6: FL | C6: 1643.31 | D6: 0.075 | E6: =IF(RAND() < 0.12, CHOOSE(RANDBETWEEN(1,4), 0, ROUND(C6 * (D6 - 0.01), 2), ROUND(C6 * (D6 + 0.01), 2), ROUND(C6 * D6 * 2, 2) ), ROUND(C6 * D6, 2) ) -> 123.25 | F6: 2020-SalesUseTaxPayable | G6: =ROUND(C6 * D6, 2) -> 123.25 | H6: =IF(ABS(E6 - G6) > 0.01, "Mismatch", "OK") -> OK | I6: {=IFERROR(XLOOKUP(XLOOKUP(A6, AP_Subledger!A:A, AP_Subledger!H:H), Tax_Rates_Reference!A:A, Tax_Rates_Reference!C:C), "")} -> 0.075 | J6: =IF(I6="", "", IF(ABS(D6 - I6) < 0.0001, TRUE, FALSE)) -> TRUE
A7: INV2025-0006 | B7: FL | C7: 19736.81 | D7: 0.07 | E7: =IF(RAND() < 0.12, CHOOSE(RANDBETWEEN(1,4), 0, ROUND(C7 * (D7 - 0.01), 2), ROUND(C7 * (D7 + 0.01), 2), ROUND(C7 * D7 * 2, 2) ), ROUND(C7 * D7, 2) ) -> 1381.58 | F7: 2020-SalesUseTaxPayable | G7: =ROUND(C7 * D7, 2) -> 1381.58 | H7: =IF(ABS(E7 - G7) > 0.01, "Mismatch", "OK") -> OK | I7: {=IFERROR(XLOOKUP(XLOOKUP(A7, AP_Subledger!A:A, AP_Subledger!H:H), Tax_Rates_Reference!A:A, Tax_Rates_Reference!C:C), "")} -> 0.07 | J7: =IF(I7="", "", IF(ABS(D7 - I7) < 0.0001, TRUE, FALSE)) -> TRUE
A8: INV2025-0007 | B8: FL | C8: 1638.04 | D8: 0.08 | E8: =IF(RAND() < 0.12, CHOOSE(RANDBETWEEN(1,4), 0, ROUND(C8 * (D8 - 0.01), 2), ROUND(C8 * (D8 + 0.01), 2), ROUND(C8 * D8 * 2, 2) ), ROUND(C8 * D8, 2) ) -> 131.04 | F8: 2020-SalesUseTaxPayable | G8: =ROUND(C8 * D8, 2) -> 131.04 | H8: =IF(ABS(E8 - G8) > 0.01, "Mismatch", "OK") -> OK | I8: {=IFERROR(XLOOKUP(XLOOKUP(A8, AP_Subledger!A:A, AP_Subledger!H:H), Tax_Rates_Reference!A:A, Tax_Rates_Reference!C:C), "")} -> 0.06 | J8: =IF(I8="", "", IF(ABS(D8 - I8) < 0.0001, TRUE, FALSE)) -> FALSE
A9: INV2025-0008 | B9: FL | C9: 23747.7 | D9: 0.075 | E9: =IF(RAND() < 0.12, CHOOSE(RANDBETWEEN(1,4), 0, ROUND(C9 * (D9 - 0.01), 2), ROUND(C9 * (D9 + 0.01), 2), ROUND(C9 * D9 * 2, 2) ), ROUND(C9 * D9, 2) ) -> 1781.08 | F9: 2020-SalesUseTaxPayable | G9: =ROUND(C9 * D9, 2) -> 1781.08 | H9: =IF(ABS(E9 - G9) > 0.01, "Mismatch", "OK") -> OK | I9: {=IFERROR(XLOOKUP(XLOOKUP(A9, AP_Subledger!A:A, AP_Subledger!H:H), Tax_Rates_Reference!A:A, Tax_Rates_Reference!C:C), "")} -> 0.075 | J9: =IF(I9="", "", IF(ABS(D9 - I9) < 0.0001, TRUE, FALSE)) -> TRUE
A10: INV2025-0009 | B10: FL | C10: 891.17 | D10: 0.04 | E10: =IF(RAND() < 0.12, CHOOSE(RANDBETWEEN(1,4), 0, ROUND(C10 * (D10 - 0.01), 2), ROUND(C10 * (D10 + 0.01), 2), ROUND(C10 * D10 * 2, 2) ), ROUND(C10 * D10, 2) ) -> 35.65 | F10: 2020-SalesUseTaxPayable | G10: =ROUND(C10 * D10, 2) -> 35.65 | H10: =IF(ABS(E10 - G10) > 0.01, "Mismatch", "OK") -> OK | I10: {=IFERROR(XLOOKUP(XLOOKUP(A10, AP_Subledger!A:A, AP_Subledger!H:H), Tax_Rates_Reference!A:A, Tax_Rates_Reference!C:C), "")} -> 0.06 | J10: =IF(I10="", "", IF(ABS(D10 - I10) < 0.0001, TRUE, FALSE)) -> FALSE
A11: INV2025-0010 | B11: FL | C11: 22778.35 | D11: 0.07 | E11: =IF(RAND() < 0.12, CHOOSE(RANDBETWEEN(1,4), 0, ROUND(C11 * (D11 - 0.01), 2), ROUND(C11 * (D11 + 0.01), 2), ROUND(C11 * D11 * 2, 2) ), ROUND(C11 * D11, 2) ) -> 1594.48 | F11: 2020-SalesUseTaxPayable | G11: =ROUND(C11 * D11, 2) -> 1594.48 | H11: =IF(ABS(E11 - G11) > 0.01, "Mismatch", "OK") -> OK | I11: {=IFERROR(XLOOKUP(XLOOKUP(A11, AP_Subledger!A:A, AP_Subledger!H:H), Tax_Rates_Reference!A:A, Tax_Rates_Reference!C:C), "")} -> 0.07 | J11: =IF(I11="", "", IF(ABS(D11 - I11) < 0.0001, TRUE, FALSE)) -> TRUE
A12: INV2025-0011 | B12: FL | C12: 5594.57 | D12: 0.065 | E12: =IF(RAND() < 0.12, CHOOSE(RANDBETWEEN(1,4), 0, ROUND(C12 * (D12 - 0.01), 2), ROUND(C12 * (D12 + 0.01), 2), ROUND(C12 * D12 * 2, 2) ), ROUND(C12 * D12, 2) ) -> 363.65 | F12: 2020-SalesUseTaxPayable | G12: =ROUND(C12 * D12, 2) -> 363.65 | H12: =IF(ABS(E12 - G12) > 0.01, "Mismatch", "OK") -> OK | I12: {=IFERROR(XLOOKUP(XLOOKUP(A12, AP_Subledger!A:A, AP_Subledger!H:H), Tax_Rates_Reference!A:A, Tax_Rates_Reference!C:C), "")} -> 0.065 | J12: =IF(I12="", "", IF(ABS(D12 - I12) < 0.0001, TRUE, FALSE)) -> TRUE
A13: INV2025-0012 | B13: FL | C13: 10181.18 | D13: 0.065 | E13: =IF(RAND() < 0.12, CHOOSE(RANDBETWEEN(1,4), 0, ROUND(C13 * (D13 - 0.01), 2), ROUND(C13 * (D13 + 0.01), 2), ROUND(C13 * D13 * 2, 2) ), ROUND(C13 * D13, 2) ) -> 661.78 | F13: 2020-SalesUseTaxPayable | G13: =ROUND(C13 * D13, 2) -> 661.78 | H13: =IF(ABS(E13 - G13) > 0.01, "Mismatch", "OK") -> OK | I13: {=IFERROR(XLOOKUP(XLOOKUP(A13, AP_Subledger!A:A, AP_Subledger!H:H), Tax_Rates_Reference!A:A, Tax_Rates_Reference!C:C), "")} -> 0.065 | J13: =IF(I13="", "", IF(ABS(D13 - I13) < 0.0001, TRUE, FALSE)) -> TRUE
... A351: INV2025-0350 | B351: FL | C351: 10886.65 | D351: 0.065 | E351: =IF(RAND() < 0.12, CHOOSE(RANDBETWEEN(1,4), 0, ROUND(C351 * (D351 - 0.01), 2), ROUND(C351 * (D351 + 0.01), 2), ROUND(C351 * D351 * 2, 2) ), ROUND(C351 * D351, 2) ) -> 707.63 | F351: 2020-SalesUseTaxPayable | G351: =ROUND(C351 * D351, 2) -> 707.63 | H351: =IF(ABS(E351 - G351) > 0.01, "Mismatch", "OK") -> OK | I351: {=IFERROR(XLOOKUP(XLOOKUP(A351, AP_Subledger!A:A, AP_Subledger!H:H), Tax_Rates_Reference!A:A, Tax_Rates_Reference!C:C), "")} -> 0.065 | J351: =IF(I351="", "", IF(ABS(D351 - I351) < 0.0001, TRUE, FALSE)) -> TRUE

Sheet Tax_Rates_Reference
A1: Tax_Jurisdiction | B1: Surtax_2025 | C1: Total_Tax_Rate_2025
A2: Hillsborough | B2: 0.015 | C2: 0.075
A3: Pinellas | B3: 0.01 | C3: 0.07
A4: Orange | B4: 0.005 | C4: 0.065
A5: Other_FL | B5: 0 | C5: 0.06

Sheet GL_Trial_Balance_Summary
A1: Account | B1: Ending_Balance
A2: 2000-AccountsPayable | B2: =SUM(AP_Subledger!J:J) * -1 -> -5034825.8
A3: 1000-Cash | B3: 350000
A4: 2020-SalesUseTaxPayable | B4: 14850
A5: 2500-LeaseLiability | B5: 420000
A6: 1800-ROUAsset | B6: 395000
A7: 6000-LeaseExpense | B7: 225000
A8: 6100-DepreciationROU | B8: 195000

Sheet Lease_Pivot

Sheet Lease_Schedule
A1: Lease_ID | B1: Start_Date | C1: Payment_Date | D1: Lease_Payment | E1: Interest_Portion | F1: Principal_Portion | G1: Ending_Lease_Liability | H1: ROU_Asset_Balance | I1: IP_Sum | J1: IP_Sum_Diff | K1: IP_Sum_Mismatch_Flag | L1: Sequence_Check
A2: LSE-001 | B2: 45658 | C2: 45658 | D2: 5684.7 | E2: 1037.27 | F2: 4647.43 | G2: 179699.41 | H2: 179699.41 | I2: 5684.700000000001 | J2: -9.094947017729282e-13 | K2: False | L2: =IF(ROW()=2, "OK", IF(C2 = EDATE(C1, 1), "OK", "Sequence Error")) -> OK
A3: LSE-001 | B3: 45658 | C3: 45689 | D3: 5684.7 | E3: 1011.19 | F3: 4673.51 | G3: 174565.14 | H3: 174565.14 | I3: 5684.700000000001 | J3: -9.094947017729282e-13 | K3: False | L3: =IF(ROW()=2, "OK", IF(C3 = EDATE(C2, 1), "OK", "Sequence Error")) -> OK
A4: LSE-001 | B4: 45658 | C4: 45717 | D4: 5684.7 | E4: 984.96 | F4: 4699.74 | G4: 169430.87 | H4: 169430.87 | I4: 5684.7 | J4: 0.0 | K4: False | L4: =IF(ROW()=2, "OK", IF(C4 = EDATE(C3, 1), "OK", "Sequence Error")) -> OK
A5: LSE-001 | B5: 45658 | C5: 45778 | D5: 5684.7 | E5: 932.07 | F5: 4752.63 | G5: 159162.33 | H5: 159162.33 | I5: 5684.7 | J5: 0.0 | K5: False | L5: =IF(ROW()=2, "OK", IF(C5 = EDATE(C4, 1), "OK", "Sequence Error")) -> Sequence Error
A6: LSE-001 | B6: 45658 | C6: 45809 | D6: 5684.7 | E6: 905.39 | F6: 4779.31 | G6: 154028.06 | H6: 154028.06 | I6: 5684.700000000001 | J6: -9.094947017729282e-13 | K6: False | L6: =IF(ROW()=2, "OK", IF(C6 = EDATE(C5, 1), "OK", "Sequence Error")) -> OK
A7: LSE-001 | B7: 45658 | C7: 45839 | D7: 5684.7 | E7: 878.57 | F7: 4806.13 | G7: 148893.79 | H7: 148893.79 | I7: 5684.7 | J7: 0.0 | K7: False | L7: =IF(ROW()=2, "OK", IF(C7 = EDATE(C6, 1), "OK", "Sequence Error")) -> OK
A8: LSE-001 | B8: 45658 | C8: 45870 | D8: 5684.7 | E8: 851.6 | F8: 4833.1 | G8: 143759.52 | H8: 143759.52 | I8: 5684.700000000001 | J8: -9.094947017729282e-13 | K8: False | L8: =IF(ROW()=2, "OK", IF(C8 = EDATE(C7, 1), "OK", "Sequence Error")) -> OK
A9: LSE-001 | B9: 45658 | C9: 45901 | D9: 5684.7 | E9: 824.48 | F9: 4860.22 | G9: 138625.25 | H9: 138625.25 | I9: 5684.700000000001 | J9: -9.094947017729282e-13 | K9: False | L9: =IF(ROW()=2, "OK", IF(C9 = EDATE(C8, 1), "OK", "Sequence Error")) -> OK
A10: LSE-001 | B10: 45658 | C10: 45931 | D10: 5684.7 | E10: 797.2 | F10: 4887.5 | G10: 133490.98 | H10: 133490.98 | I10: 5684.7 | J10: 0.0 | K10: False | L10: =IF(ROW()=2, "OK", IF(C10 = EDATE(C9, 1), "OK", "Sequence Error")) -> OK
A11: LSE-001 | B11: 45658 | C11: 45962 | D11: 5684.7 | E11: 769.78 | F11: 4914.92 | G11: 128356.71 | H11: 128356.71 | I11: 5684.7 | J11: 0.0 | K11: False | L11: =IF(ROW()=2, "OK", IF(C11 = EDATE(C10, 1), "OK", "Sequence Error")) -> OK
A12: LSE-001 | B12: 45658 | C12: 45992 | D12: 5684.7 | E12: 742.19 | F12: 4942.51 | G12: 123222.44 | H12: 123222.44 | I12: 5684.700000000001 | J12: -9.094947017729282e-13 | K12: False | L12: =IF(ROW()=2, "OK", IF(C12 = EDATE(C11, 1), "OK", "Sequence Error")) -> OK
A13: LSE-001 | B13: 45658 | C13: 46023 | D13: 5684.7 | E13: 714.46 | F13: 4970.24 | G13: 118088.17 | H13: 118088.17 | I13: 5684.7 | J13: 0.0 | K13: False | L13: =IF(ROW()=2, "OK", IF(C13 = EDATE(C12, 1), "OK", "Sequence Error")) -> OK
... A121: LSE-004 | B121: 45809 | C121: 46508 | D121: 4147.33 | E121: 29.13 | F121: 4118.2 | G121: 0 | H121: 0 | I121: 4147.33 | J121: 0.0 | K121: False | L121: =IF(ROW()=2, "OK", IF(C121 = EDATE(C120, 1), "OK", "Sequence Error")) -> OK

Sheet Reconciliation_Summary
A1: AP_Unpaid_Total | B1: GL_AP_Control_Balance_Cell | C1: Variance (GL − Subledger) | D1: GL_Missing_Items | E1: Paid_per_AP | F1: Payments_per_Bank | G1: Variance_bank | H1: Paid_no_bank_match | I1: duplicate_payments | J1: Invoice_Tax_Total | K1: GL_Tax_Payable | L1: Variance_GL_Invoice_Tax | M1: Lease_Liability_Total | N1: ROU_Asset_Total | O1: GL_Lease_Liability | P1: GL_ROU_Asset | Q1: GL_Lease_Liability_Variance | R1: GL_ROU_Asset_Variance | S1: Sequence_Error
A2: =SUMIFS(AP_Subledger!J:J, AP_Subledger!O:O, TRUE) -> 1134501.7 | B2: {=INDEX(GL_AP_Control!B:B, MATCH("2025-12", GL_AP_Control!A:A, 0))} -> 1109192.51 | C2: =B2-A2 -> -25309.16 | D2: =IF(COUNTIF(AP_Subledger!P:P, "Missing")>0, "Missing Items", "OK") -> OK | E2: =SUMIFS(AP_Subledger!J:J, AP_Subledger!K:K, TRUE) -> 3900324.1 | F2: =SUM(Bank_Txns!E:E) * -1 -> 4058113.5 | G2: =F2-E2 -> 157789.39 | H2: =COUNTIF(AP_Subledger!Q:Q, "Paid but No Bank Match") -> 265 | I2: =COUNTIF(Bank_Txns!J:J, "Duplicate Payment") -> 16 | J2: =SUM(Tax_Detail!E:E) -> 329408.99 | K2: {=XLOOKUP("2020-SalesUseTaxPayable", GL_Trial_Balance_Summary!A:A, GL_Trial_Balance_Summary!B:B)} -> 14850 | L2: =K2-J2 -> -314558.99 | M2: =SUM(Lease_Pivot!C5:C8) -> 462441.95 | N2: =SUM(Lease_Pivot!D5:D8) -> 462441.95 | O2: {=XLOOKUP("2500-LeaseLiability", GL_Trial_Balance_Summary!A:A, GL_Trial_Balance_Summary!B:B)} -> 420000 | P2: {=XLOOKUP("1800-ROUAsset", GL_Trial_Balance_Summary!A:A, GL_Trial_Balance_Summary!B:B)} -> 395000 | Q2: =O2-M2 -> -42441.95 | R2: =P2-N2 -> -67441.95 | S2: =COUNTIF(Lease_Schedule!L:L, "Sequence Error") -> 6
